<?xml version="1.0" encoding="utf-8"?>
<!-- This URDF was automatically created by SolidWorks to URDF Exporter! Originally created by Stephen Brawner (brawner@gmail.com) 
     Commit Version: 1.6.0-4-g7f85cfe  Build Version: 1.6.7995.38578
     For more information, please see http://wiki.ros.org/sw_urdf_exporter -->
<robot
  name="ROS_Module_Assembly_v4">
  <link
    name="base_link">
    <inertial>
      <origin
        xyz="-0.031724 -0.12886 0.039095"
        rpy="0 0 0" />
      <mass
        value="2.1961" />
      <inertia
        ixx="0.0063697"
        ixy="-3.3879E-05"
        ixz="-1.3091E-07"
        iyy="0.0035478"
        iyz="1.1651E-06"
        izz="0.009033" />
    </inertial>
    <visual>
      <origin
        xyz="0 0 0"
        rpy="0 0 0" />
      <geometry>
        <mesh
          filename="package://ROS_Module_Assembly_v4/meshes/base_link.STL" />
      </geometry>
      <material
        name="">
        <color
          rgba="0.79216 0.81961 0.93333 1" />
      </material>
    </visual>
    <collision>
      <origin
        xyz="0 0 0"
        rpy="0 0 0" />
      <geometry>
        <mesh
          filename="package://ROS_Module_Assembly_v4/meshes/base_link.STL" />
      </geometry>
    </collision>
  </link>
  <link
    name="input_transl_motor">
    <inertial>
      <origin
        xyz="-1.865E-05 0.047153 -6.6546E-05"
        rpy="0 0 0" />
      <mass
        value="0.032255" />
      <inertia
        ixx="1.5951E-05"
        ixy="1.8513E-09"
        ixz="3.575E-09"
        iyy="2.7304E-06"
        iyz="6.6055E-09"
        izz="1.5963E-05" />
    </inertial>
    <visual>
      <origin
        xyz="0 0 0"
        rpy="0 0 0" />
      <geometry>
        <mesh
          filename="package://ROS_Module_Assembly_v4/meshes/input_transl_motor.STL" />
      </geometry>
      <material
        name="">
        <color
          rgba="0.79216 0.81961 0.93333 1" />
      </material>
    </visual>
    <collision>
      <origin
        xyz="0 0 0"
        rpy="0 0 0" />
      <geometry>
        <mesh
          filename="package://ROS_Module_Assembly_v4/meshes/input_transl_motor.STL" />
      </geometry>
    </collision>
  </link>
  <joint
    name="base_to_input_transport"
    type="continuous">
    <origin
      xyz="-0.07615 -0.16897 0.008"
      rpy="-1.5708 0 -1.2874" />
    <parent
      link="base_link" />
    <child
      link="input_transl_motor" />
    <axis
      xyz="0 1 0" />
  </joint>
  <link
    name="vert_bevel_shaft_transl">
    <inertial>
      <origin
        xyz="1.2062E-06 2.1092E-05 -0.034965"
        rpy="0 0 0" />
      <mass
        value="0.11927" />
      <inertia
        ixx="0.00012322"
        ixy="6.9262E-10"
        ixz="-2.6667E-09"
        iyy="0.00012323"
        iyz="-4.6605E-08"
        izz="6.1731E-05" />
    </inertial>
    <visual>
      <origin
        xyz="0 0 0"
        rpy="0 0 0" />
      <geometry>
        <mesh
          filename="package://ROS_Module_Assembly_v4/meshes/vert_bevel_shaft_transl.STL" />
      </geometry>
      <material
        name="">
        <color
          rgba="0.79216 0.81961 0.93333 1" />
      </material>
    </visual>
    <collision>
      <origin
        xyz="0 0 0"
        rpy="0 0 0" />
      <geometry>
        <mesh
          filename="package://ROS_Module_Assembly_v4/meshes/vert_bevel_shaft_transl.STL" />
      </geometry>
    </collision>
  </link>
  <joint
    name="input_transl_to_vert_bevel"
    type="continuous">
    <origin
      xyz="-0.14094 0.008 0.12037"
      rpy="1.5708 -1.2874 0" />
    <parent
      link="input_transl_motor" />
    <child
      link="vert_bevel_shaft_transl" />
    <axis
      xyz="0 0 -1" />
  </joint>
  <link
    name="wheel">
    <inertial>
      <origin
        xyz="0.00445341511356639 -3.96137631562821E-06 -0.000161993357750634"
        rpy="0 0 0" />
      <mass
        value="2.07570429178156" />
      <inertia
        ixx="0.0322800434555573"
        ixy="-1.64374510444238E-09"
        ixz="-0.000559220222904143"
        iyy="0.016614986162682"
        iyz="-3.95902399334139E-09"
        izz="0.0166349899495676" />
    </inertial>
    <visual>
      <origin
        xyz="0 0 0"
        rpy="0 0 0" />
      <geometry>
        <mesh
          filename="package://ROS_Module_Assembly_v4/meshes/wheel.STL" />
      </geometry>
      <material
        name="">
        <color
          rgba="0.792156862745098 0.819607843137255 0.933333333333333 1" />
      </material>
    </visual>
    <collision>
      <origin
        xyz="0 0 0"
        rpy="0 0 0" />
      <geometry>
        <mesh
          filename="package://ROS_Module_Assembly_v4/meshes/wheel.STL" />
      </geometry>
    </collision>
  </link>
  <joint
    name="vert_bevel_to_wheel"
    type="continuous">
    <origin
      xyz="0 0 0.336"
      rpy="-1.5708 0 1.5437" />
    <parent
      link="vert_bevel_shaft_transl" />
    <child
      link="wheel" />
    <axis
      xyz="-0.99936 0 0.03567" />
  </joint>
  <link
    name="input_rot_motor">
    <inertial>
      <origin
        xyz="8.5778E-05 0.032009 -8.9767E-10"
        rpy="0 0 0" />
      <mass
        value="0.025091" />
      <inertia
        ixx="7.1988E-06"
        ixy="-1.3589E-09"
        ixz="-2.0976E-13"
        iyy="2.3424E-06"
        iyz="-2.9086E-13"
        izz="7.1717E-06" />
    </inertial>
    <visual>
      <origin
        xyz="0 0 0"
        rpy="0 0 0" />
      <geometry>
        <mesh
          filename="package://ROS_Module_Assembly_v4/meshes/input_rot_motor.STL" />
      </geometry>
      <material
        name="">
        <color
          rgba="0.79216 0.81961 0.93333 1" />
      </material>
    </visual>
    <collision>
      <origin
        xyz="0 0 0"
        rpy="0 0 0" />
      <geometry>
        <mesh
          filename="package://ROS_Module_Assembly_v4/meshes/input_rot_motor.STL" />
      </geometry>
    </collision>
  </link>
  <joint
    name="base_to_input_rot"
    type="continuous">
    <origin
      xyz="0.00425 -0.18427 0.009"
      rpy="-1.5708 0 0.52203" />
    <parent
      link="base_link" />
    <child
      link="input_rot_motor" />
    <axis
      xyz="0 -1 0" />
  </joint>
  <link
    name="fork">
    <inertial>
      <origin
        xyz="0.0011495 0.019822 0.17644"
        rpy="0 0 0" />
      <mass
        value="2.1939" />
      <inertia
        ixx="0.0090713"
        ixy="0.00015215"
        ixz="2.4121E-06"
        iyy="0.01148"
        iyz="-2.9545E-05"
        izz="0.0039097" />
    </inertial>
    <visual>
      <origin
        xyz="0 0 0"
        rpy="0 0 0" />
      <geometry>
        <mesh
          filename="package://ROS_Module_Assembly_v4/meshes/fork.STL" />
      </geometry>
      <material
        name="">
        <color
          rgba="0.79216 0.81961 0.93333 1" />
      </material>
    </visual>
    <collision>
      <origin
        xyz="0 0 0"
        rpy="0 0 0" />
      <geometry>
        <mesh
          filename="package://ROS_Module_Assembly_v4/meshes/fork.STL" />
      </geometry>
    </collision>
  </link>
  <joint
    name="input_transl_to_rot_fork"
    type="continuous">
    <origin
      xyz="0.088199 0.009 0.16184"
      rpy="1.5708 0.52203 0" />
    <parent
      link="input_rot_motor" />
    <child
      link="fork" />
    <axis
      xyz="0 0 1" />
  </joint>
</robot>